<?xml version="1.0" ?>
<!-- =================================================================================== -->
<!-- |    This document was autogenerated by xacro from /home/hiro/ros2/AIC_car_2025/install/robot_gazebo/share/robot_gazebo/launch/../urdf/robot.urdf.xacro | -->
<!-- |    EDITING THIS FILE BY HAND IS NOT RECOMMENDED                                 | -->
<!-- =================================================================================== -->
<robot name="my_robot">
  <!-- 宏:颜色设置 -->
  <material name="black">
    <color rgba="0.0 0.0 0.0 1.0"/>
  </material>
  <material name="yellow">
    <color rgba="1.0 1.0 0.0 1.0"/>
  </material>
  <!-- 底盘主体 -->
  <link name="base_link">
    <visual>
      <geometry>
        <cylinder length="0.08" radius="0.1"/>
      </geometry>
      <origin rpy="0 0 0" xyz="0 0 0"/>
      <material name="yellow">
        <color rgba="0.5 0.3 0.0 0.5"/>
      </material>
    </visual>
  </link>
  <link name="front_left_wheel">
    <visual>
      <geometry>
        <cylinder length="0.02" radius="0.04"/>
      </geometry>
      <origin rpy="1.5707963 0 0" xyz="0 0 0"/>
      <material name="yellow"/>
    </visual>
    <collision>
      <geometry>
        <cylinder length="0.02" radius="0.04"/>
      </geometry>
      <origin rpy="1.5707963 0 0" xyz="0 0 0"/>
      <!-- 添加摩擦力 -->
      <surface>
        <friction>
          <ode>
            <mu>0.2</mu>
            <!-- 主摩擦系数 -->
            <mu2>0.2</mu2>
            <!-- 次摩擦系数 -->
          </ode>
        </friction>
      </surface>
    </collision>
    <inertial>
      <mass value="0.1"/>
      <inertia ixx="4.333333333333333e-05" ixy="0" ixz="0" iyy="4.333333333333333e-05" iyz="0" izz="8e-05"/>
    </inertial>
  </link>
  <joint name="front_left_wheel_joint" type="continuous">
    <parent link="base_link"/>
    <child link="front_left_wheel"/>
    <origin rpy="0 0 0" xyz="0.1 0.1 -0.010000000000000002"/>
    <axis xyz="0 1 0"/>
  </joint>
  <gazebo reference="front_left_wheel">
    <material>Gazebo/yellow</material>
  </gazebo>
  <link name="front_right_wheel">
    <visual>
      <geometry>
        <cylinder length="0.02" radius="0.04"/>
      </geometry>
      <origin rpy="1.5707963 0 0" xyz="0 0 0"/>
      <material name="yellow"/>
    </visual>
    <collision>
      <geometry>
        <cylinder length="0.02" radius="0.04"/>
      </geometry>
      <origin rpy="1.5707963 0 0" xyz="0 0 0"/>
      <!-- 添加摩擦力 -->
      <surface>
        <friction>
          <ode>
            <mu>0.2</mu>
            <!-- 主摩擦系数 -->
            <mu2>0.2</mu2>
            <!-- 次摩擦系数 -->
          </ode>
        </friction>
      </surface>
    </collision>
    <inertial>
      <mass value="0.1"/>
      <inertia ixx="4.333333333333333e-05" ixy="0" ixz="0" iyy="4.333333333333333e-05" iyz="0" izz="8e-05"/>
    </inertial>
  </link>
  <joint name="front_right_wheel_joint" type="continuous">
    <parent link="base_link"/>
    <child link="front_right_wheel"/>
    <origin rpy="0 0 0" xyz="0.1 -0.1 -0.010000000000000002"/>
    <axis xyz="0 1 0"/>
  </joint>
  <gazebo reference="front_right_wheel">
    <material>Gazebo/yellow</material>
  </gazebo>
  <link name="rear_left_wheel">
    <visual>
      <geometry>
        <cylinder length="0.02" radius="0.04"/>
      </geometry>
      <origin rpy="1.5707963 0 0" xyz="0 0 0"/>
      <material name="yellow"/>
    </visual>
    <collision>
      <geometry>
        <cylinder length="0.02" radius="0.04"/>
      </geometry>
      <origin rpy="1.5707963 0 0" xyz="0 0 0"/>
      <!-- 添加摩擦力 -->
      <surface>
        <friction>
          <ode>
            <mu>0.2</mu>
            <!-- 主摩擦系数 -->
            <mu2>0.2</mu2>
            <!-- 次摩擦系数 -->
          </ode>
        </friction>
      </surface>
    </collision>
    <inertial>
      <mass value="0.1"/>
      <inertia ixx="4.333333333333333e-05" ixy="0" ixz="0" iyy="4.333333333333333e-05" iyz="0" izz="8e-05"/>
    </inertial>
  </link>
  <joint name="rear_left_wheel_joint" type="continuous">
    <parent link="base_link"/>
    <child link="rear_left_wheel"/>
    <origin rpy="0 0 0" xyz="-0.1 0.1 -0.010000000000000002"/>
    <axis xyz="0 1 0"/>
  </joint>
  <gazebo reference="rear_left_wheel">
    <material>Gazebo/yellow</material>
  </gazebo>
  <link name="rear_right_wheel">
    <visual>
      <geometry>
        <cylinder length="0.02" radius="0.04"/>
      </geometry>
      <origin rpy="1.5707963 0 0" xyz="0 0 0"/>
      <material name="yellow"/>
    </visual>
    <collision>
      <geometry>
        <cylinder length="0.02" radius="0.04"/>
      </geometry>
      <origin rpy="1.5707963 0 0" xyz="0 0 0"/>
      <!-- 添加摩擦力 -->
      <surface>
        <friction>
          <ode>
            <mu>0.2</mu>
            <!-- 主摩擦系数 -->
            <mu2>0.2</mu2>
            <!-- 次摩擦系数 -->
          </ode>
        </friction>
      </surface>
    </collision>
    <inertial>
      <mass value="0.1"/>
      <inertia ixx="4.333333333333333e-05" ixy="0" ixz="0" iyy="4.333333333333333e-05" iyz="0" izz="8e-05"/>
    </inertial>
  </link>
  <joint name="rear_right_wheel_joint" type="continuous">
    <parent link="base_link"/>
    <child link="rear_right_wheel"/>
    <origin rpy="0 0 0" xyz="-0.1 -0.1 -0.010000000000000002"/>
    <axis xyz="0 1 0"/>
  </joint>
  <gazebo reference="rear_right_wheel">
    <material>Gazebo/yellow</material>
  </gazebo>
  <!-- ========== ros2_control 定义 ========== -->
  <ros2_control name="GazeboSystem" type="system">
    <hardware>
      <plugin>gazebo_ros2_control/GazeboSystem</plugin>
    </hardware>
    <!-- 四个麦轮 joint -->
    <joint name="front_left_wheel_joint">
      <command_interface name="velocity"/>
      <state_interface name="velocity"/>
    </joint>
    <joint name="front_right_wheel_joint">
      <command_interface name="velocity"/>
      <state_interface name="velocity"/>
    </joint>
    <joint name="rear_left_wheel_joint">
      <command_interface name="velocity"/>
      <state_interface name="velocity"/>
    </joint>
    <joint name="rear_right_wheel_joint">
      <command_interface name="velocity"/>
      <state_interface name="velocity"/>
    </joint>
  </ros2_control>
  <gazebo>
    <plugin filename="libgazebo_ros2_control.so" name="gazebo_ros2_control">
      <parameters>/home/hiro/ros2/AIC_car_2025/robot_gazebo/urdf/mecanum_controllers.yaml</parameters>
    </plugin>
  </gazebo>
  <controller name="mecanum_controller" type="mecanum_drive_controller/MecanumDriveController">
    <ros>
      <namespace>/</namespace>
      <!-- <parameters>
        <param name="front_left_wheel_command_joint_name" value="front_left_wheel_joint"/>
        <param name="front_right_wheel_command_joint_name" value="front_right_wheel_joint"/>
        <param name="rear_left_wheel_command_joint_name" value="rear_left_wheel_joint"/>
        <param name="rear_right_wheel_command_joint_name" value="rear_right_wheel_joint"/>
        <param name="front_left_wheel_state_joint_name" value="front_left_wheel_joint"/>
        <param name="front_right_wheel_state_joint_name" value="front_right_wheel_joint"/>
        <param name="rear_left_wheel_state_joint_name" value="rear_left_wheel_joint"/>
        <param name="rear_right_wheel_state_joint_name" value="rear_right_wheel_joint"/>
        <param name="wheel_radius" value="0.05"/>
        <param name="wheel_separation_x" value="0.3"/>
        <param name="wheel_separation_y" value="0.25"/>
        <param name="command_interface" value="['velocity']"/>
        <param name="state_interface" value="['velocity']"/>
        <param name="publish_rate" value="50.0"/>
      </parameters> -->
    </ros>
  </controller>
  <!-- 摄像头安装的z坐标:底盘高度 / 2 + 摄像头高度 / 2  -->
  <!-- 摄像头质量 -->
  <!-- 摄像头关节以及link -->
  <link name="camera">
    <visual>
      <geometry>
        <box size="0.01 0.025 0.025"/>
      </geometry>
      <origin rpy="0.0 0.0 0.0" xyz="0.0 0.0 0.0"/>
      <material name="black"/>
    </visual>
    <collision>
      <geometry>
        <box size="0.01 0.025 0.025"/>
      </geometry>
      <origin rpy="0.0 0.0 0.0" xyz="0.0 0.0 0.0"/>
    </collision>
    <inertial>
      <mass value="0.01"/>
      <inertia ixx="6.041666666666668e-07" ixy="0" ixz="0" iyy="6.041666666666668e-07" iyz="0" izz="1.041666666666667e-06"/>
    </inertial>
  </link>
  <joint name="camera2base_link" type="fixed">
    <parent link="base_link"/>
    <child link="camera"/>
    <origin xyz="0.08 0.0 0.052500000000000005"/>
  </joint>
  <gazebo reference="camera">
    <material>Gazebo/Blue</material>
  </gazebo>
  <!-- 支架安装的z坐标:底盘高度 / 2 + 支架高度 / 2  -->
  <!-- 支架质量 -->
  <link name="support">
    <visual>
      <geometry>
        <cylinder length="0.05" radius="0.01"/>
      </geometry>
      <origin rpy="0.0 0.0 0.0" xyz="0.0 0.0 0.0"/>
      <material name="red">
        <color rgba="0.8 0.2 0.0 0.8"/>
      </material>
    </visual>
    <collision>
      <geometry>
        <cylinder length="0.05" radius="0.01"/>
      </geometry>
      <origin rpy="0.0 0.0 0.0" xyz="0.0 0.0 0.0"/>
    </collision>
    <inertial>
      <mass value="0.02"/>
      <inertia ixx="4.666666666666667e-06" ixy="0" ixz="0" iyy="4.666666666666667e-06" iyz="0" izz="1.0000000000000002e-06"/>
    </inertial>
  </link>
  <joint name="support2base_link" type="fixed">
    <parent link="base_link"/>
    <child link="support"/>
    <origin xyz="0.0 0.0 0.065"/>
  </joint>
  <gazebo reference="support">
    <material>Gazebo/White</material>
  </gazebo>
  <!-- 雷达质量 -->
  <!-- 雷达关节以及link -->
  <link name="laser">
    <visual>
      <geometry>
        <cylinder length="0.05" radius="0.03"/>
      </geometry>
      <origin rpy="0.0 0.0 0.0" xyz="0.0 0.0 0.0"/>
      <material name="black"/>
    </visual>
    <collision>
      <geometry>
        <cylinder length="0.05" radius="0.03"/>
      </geometry>
      <origin rpy="0.0 0.0 0.0" xyz="0.0 0.0 0.0"/>
    </collision>
    <inertial>
      <mass value="0.1"/>
      <inertia ixx="4.333333333333333e-05" ixy="0" ixz="0" iyy="4.333333333333333e-05" iyz="0" izz="4.4999999999999996e-05"/>
    </inertial>
  </link>
  <joint name="laser2support" type="fixed">
    <parent link="support"/>
    <child link="laser"/>
    <origin xyz="0.0 0.0 0.05"/>
  </joint>
  <gazebo reference="laser">
    <material>Gazebo/Black</material>
  </gazebo>
  <!-- 加载绝对位姿获取插件 -->
  <gazebo>
    <plugin filename="libodom_plugin.so" name="odom_plugin">
      <topic_name>/absolute_pose</topic_name>
      <publish_rate>50</publish_rate>
    </plugin>
  </gazebo>
</robot>
