<?xml version="1.0" ?>
<!-- =================================================================================== -->
<!-- |    This document was autogenerated by xacro from /home/hiro/ros2/AIC_car_2025/install/robot_gazebo/share/robot_gazebo/launch/../urdf/robot.urdf.xacro | -->
<!-- |    EDITING THIS FILE BY HAND IS NOT RECOMMENDED                                 | -->
<!-- =================================================================================== -->
<robot name="my_robot">
  <!-- 宏:颜色设置 -->
  <material name="black">
    <color rgba="0.0 0.0 0.0 1.0"/>
  </material>
  <material name="yellow">
    <color rgba="1.0 1.0 0.0 1.0"/>
  </material>
  <!-- 虚拟的 root link（无质量，无惯性） -->
  <link name="base_footprint"/>
  <!-- 原 base_link 是 base_footprint 的子链接 -->
  <joint name="base_footprint_to_base_link" type="fixed">
    <parent link="base_footprint"/>
    <child link="base_link"/>
    <origin rpy="0 0 0" xyz="0 0 0.0425"/>
  </joint>
  <!-- 底盘主体 -->
  <link name="base_link">
    <!-- 可视化 -->
    <visual>
      <geometry>
        <cylinder length="0.08" radius="0.1"/>
      </geometry>
      <origin rpy="0 0 0" xyz="0 0 0"/>
      <material name="yellow">
        <color rgba="0.5 0.3 0.0 0.5"/>
      </material>
    </visual>
    <!-- 碰撞体 -->
    <collision>
      <geometry>
        <cylinder length="0.08" radius="0.1"/>
      </geometry>
      <origin rpy="0 0 0" xyz="0 0 0"/>
    </collision>
    <!-- 惯性矩阵 -->
    <inertial>
      <mass value="2.0"/>
      <origin rpy="0 0 0" xyz="0 0 0"/>
      <inertia ixx="0.006066666666666668" ixy="0" ixz="0" iyy="0.006066666666666668" iyz="0" izz="0.1"/>
    </inertial>
  </link>
  <link name="front_left_wheel">
    <visual>
      <geometry>
        <cylinder length="0.02" radius="0.0325"/>
      </geometry>
      <origin rpy="1.5707963 0 0" xyz="0 0 0"/>
      <material name="yellow"/>
    </visual>
    <collision>
      <geometry>
        <cylinder length="0.02" radius="0.0325"/>
      </geometry>
      <origin rpy="1.5707963 0 0" xyz="0 0 0"/>
      <!-- 添加摩擦力 -->
      <surface>
        <friction>
          <ode>
            <mu>1.0</mu>
            <!-- 主摩擦系数 -->
            <mu2>1.0</mu2>
            <!-- 次摩擦系数 -->
          </ode>
        </friction>
      </surface>
    </collision>
    <inertial>
      <mass value="0.1"/>
      <inertia ixx="2.9739583333333336e-05" ixy="0" ixz="0" iyy="2.9739583333333336e-05" iyz="0" izz="5.281250000000001e-05"/>
    </inertial>
  </link>
  <joint name="front_left_wheel_joint" type="continuous">
    <parent link="base_link"/>
    <child link="front_left_wheel"/>
    <origin rpy="0 0 0" xyz="0.08 0.08 -0.0175"/>
    <axis xyz="0 1 0"/>
  </joint>
  <gazebo reference="front_left_wheel">
    <material>Gazebo/yellow</material>
  </gazebo>
  <link name="front_right_wheel">
    <visual>
      <geometry>
        <cylinder length="0.02" radius="0.0325"/>
      </geometry>
      <origin rpy="1.5707963 0 0" xyz="0 0 0"/>
      <material name="yellow"/>
    </visual>
    <collision>
      <geometry>
        <cylinder length="0.02" radius="0.0325"/>
      </geometry>
      <origin rpy="1.5707963 0 0" xyz="0 0 0"/>
      <!-- 添加摩擦力 -->
      <surface>
        <friction>
          <ode>
            <mu>1.0</mu>
            <!-- 主摩擦系数 -->
            <mu2>1.0</mu2>
            <!-- 次摩擦系数 -->
          </ode>
        </friction>
      </surface>
    </collision>
    <inertial>
      <mass value="0.1"/>
      <inertia ixx="2.9739583333333336e-05" ixy="0" ixz="0" iyy="2.9739583333333336e-05" iyz="0" izz="5.281250000000001e-05"/>
    </inertial>
  </link>
  <joint name="front_right_wheel_joint" type="continuous">
    <parent link="base_link"/>
    <child link="front_right_wheel"/>
    <origin rpy="0 0 0" xyz="0.08 -0.08 -0.0175"/>
    <axis xyz="0 1 0"/>
  </joint>
  <gazebo reference="front_right_wheel">
    <material>Gazebo/yellow</material>
  </gazebo>
  <link name="rear_left_wheel">
    <visual>
      <geometry>
        <cylinder length="0.02" radius="0.0325"/>
      </geometry>
      <origin rpy="1.5707963 0 0" xyz="0 0 0"/>
      <material name="yellow"/>
    </visual>
    <collision>
      <geometry>
        <cylinder length="0.02" radius="0.0325"/>
      </geometry>
      <origin rpy="1.5707963 0 0" xyz="0 0 0"/>
      <!-- 添加摩擦力 -->
      <surface>
        <friction>
          <ode>
            <mu>1.0</mu>
            <!-- 主摩擦系数 -->
            <mu2>1.0</mu2>
            <!-- 次摩擦系数 -->
          </ode>
        </friction>
      </surface>
    </collision>
    <inertial>
      <mass value="0.1"/>
      <inertia ixx="2.9739583333333336e-05" ixy="0" ixz="0" iyy="2.9739583333333336e-05" iyz="0" izz="5.281250000000001e-05"/>
    </inertial>
  </link>
  <joint name="rear_left_wheel_joint" type="continuous">
    <parent link="base_link"/>
    <child link="rear_left_wheel"/>
    <origin rpy="0 0 0" xyz="-0.08 0.08 -0.0175"/>
    <axis xyz="0 1 0"/>
  </joint>
  <gazebo reference="rear_left_wheel">
    <material>Gazebo/yellow</material>
  </gazebo>
  <link name="rear_right_wheel">
    <visual>
      <geometry>
        <cylinder length="0.02" radius="0.0325"/>
      </geometry>
      <origin rpy="1.5707963 0 0" xyz="0 0 0"/>
      <material name="yellow"/>
    </visual>
    <collision>
      <geometry>
        <cylinder length="0.02" radius="0.0325"/>
      </geometry>
      <origin rpy="1.5707963 0 0" xyz="0 0 0"/>
      <!-- 添加摩擦力 -->
      <surface>
        <friction>
          <ode>
            <mu>1.0</mu>
            <!-- 主摩擦系数 -->
            <mu2>1.0</mu2>
            <!-- 次摩擦系数 -->
          </ode>
        </friction>
      </surface>
    </collision>
    <inertial>
      <mass value="0.1"/>
      <inertia ixx="2.9739583333333336e-05" ixy="0" ixz="0" iyy="2.9739583333333336e-05" iyz="0" izz="5.281250000000001e-05"/>
    </inertial>
  </link>
  <joint name="rear_right_wheel_joint" type="continuous">
    <parent link="base_link"/>
    <child link="rear_right_wheel"/>
    <origin rpy="0 0 0" xyz="-0.08 -0.08 -0.0175"/>
    <axis xyz="0 1 0"/>
  </joint>
  <gazebo reference="rear_right_wheel">
    <material>Gazebo/yellow</material>
  </gazebo>
  <!-- 摄像头质量 -->
  <!-- 摄像头 Link -->
  <link name="camera1">
    <visual>
      <geometry>
        <box size="0.01 0.025 0.025"/>
      </geometry>
      <origin rpy="0 0 0" xyz="0 0 0"/>
      <material name="camera_blue">
        <color rgba="0.2 0.5 0.8 1.0"/>
      </material>
    </visual>
    <collision>
      <geometry>
        <box size="0.01 0.025 0.025"/>
      </geometry>
      <origin rpy="0 0 0" xyz="0 0 0"/>
    </collision>
    <inertial>
      <mass value="0.01"/>
      <inertia ixx="6.041666666666668e-07" ixy="0" ixz="0" iyy="6.041666666666668e-07" iyz="0" izz="1.041666666666667e-06"/>
    </inertial>
  </link>
  <!-- 摄像头 Joint -->
  <joint name="camera1_joint" type="fixed">
    <parent link="base_link"/>
    <child link="camera1"/>
    <origin rpy="0 0 1.5708" xyz="0.0 0.08 0.052500000000000005"/>
  </joint>
  <!-- Gazebo 材质 -->
  <gazebo reference="camera1">
    <material>Gazebo/Blue</material>
  </gazebo>
  <!-- Gazebo 摄像头传感器插件 -->
  <gazebo reference="camera1">
    <sensor name="camera1_sensor" type="camera">
      <update_rate>30.0</update_rate>
      <visualize>true</visualize>
      <!-- 在 Gazebo 中显示摄像头视锥 -->
      <camera name="camera1">
        <horizontal_fov>1.6</horizontal_fov>
        <!-- 90度视角 = 1.6 弧度 -->
        <image>
          <width>1280</width>
          <!-- 720p 宽度 -->
          <height>720</height>
          <!-- 720p 高度 -->
          <format>R8G8B8</format>
        </image>
        <clip>
          <near>0.02</near>
          <far>10.0</far>
        </clip>
        <noise>
          <type>gaussian</type>
          <mean>0.0</mean>
          <stddev>0.007</stddev>
        </noise>
      </camera>
      <plugin filename="libgazebo_ros_camera.so" name="camera1_controller">
        <ros>
          <namespace/>
          <remapping>image_raw:=camera1/image_raw</remapping>
          <remapping>camera_info:=camera1/camera_info</remapping>
        </ros>
        <camera_name>camera1</camera_name>
        <frame_name>camera1</frame_name>
        <hack_baseline>0.07</hack_baseline>
      </plugin>
    </sensor>
  </gazebo>
  <!-- 摄像头 Link -->
  <link name="camera2">
    <visual>
      <geometry>
        <box size="0.01 0.025 0.025"/>
      </geometry>
      <origin rpy="0 0 0" xyz="0 0 0"/>
      <material name="camera_blue">
        <color rgba="0.2 0.5 0.8 1.0"/>
      </material>
    </visual>
    <collision>
      <geometry>
        <box size="0.01 0.025 0.025"/>
      </geometry>
      <origin rpy="0 0 0" xyz="0 0 0"/>
    </collision>
    <inertial>
      <mass value="0.01"/>
      <inertia ixx="6.041666666666668e-07" ixy="0" ixz="0" iyy="6.041666666666668e-07" iyz="0" izz="1.041666666666667e-06"/>
    </inertial>
  </link>
  <!-- 摄像头 Joint -->
  <joint name="camera2_joint" type="fixed">
    <parent link="base_link"/>
    <child link="camera2"/>
    <origin rpy="0 0 -1.5708" xyz="0.0 -0.08 0.052500000000000005"/>
  </joint>
  <!-- Gazebo 材质 -->
  <gazebo reference="camera2">
    <material>Gazebo/Blue</material>
  </gazebo>
  <!-- Gazebo 摄像头传感器插件 -->
  <gazebo reference="camera2">
    <sensor name="camera2_sensor" type="camera">
      <update_rate>30.0</update_rate>
      <visualize>true</visualize>
      <!-- 在 Gazebo 中显示摄像头视锥 -->
      <camera name="camera2">
        <horizontal_fov>1.6</horizontal_fov>
        <!-- 90度视角 = 1.6 弧度 -->
        <image>
          <width>1280</width>
          <!-- 720p 宽度 -->
          <height>720</height>
          <!-- 720p 高度 -->
          <format>R8G8B8</format>
        </image>
        <clip>
          <near>0.02</near>
          <far>10.0</far>
        </clip>
        <noise>
          <type>gaussian</type>
          <mean>0.0</mean>
          <stddev>0.007</stddev>
        </noise>
      </camera>
      <plugin filename="libgazebo_ros_camera.so" name="camera2_controller">
        <ros>
          <namespace/>
          <remapping>image_raw:=camera2/image_raw</remapping>
          <remapping>camera_info:=camera2/camera_info</remapping>
        </ros>
        <camera_name>camera2</camera_name>
        <frame_name>camera2</frame_name>
        <hack_baseline>0.07</hack_baseline>
      </plugin>
    </sensor>
  </gazebo>
  <!-- 支架安装的z坐标:底盘高度 / 2 + 支架高度 / 2  -->
  <!-- 支架质量 -->
  <link name="support">
    <visual>
      <geometry>
        <cylinder length="0.05" radius="0.01"/>
      </geometry>
      <origin rpy="0.0 0.0 0.0" xyz="0.0 0.0 0.0"/>
      <material name="red">
        <color rgba="0.8 0.2 0.0 0.8"/>
      </material>
    </visual>
    <collision>
      <geometry>
        <cylinder length="0.05" radius="0.01"/>
      </geometry>
      <origin rpy="0.0 0.0 0.0" xyz="0.0 0.0 0.0"/>
    </collision>
    <inertial>
      <mass value="0.02"/>
      <inertia ixx="4.666666666666667e-06" ixy="0" ixz="0" iyy="4.666666666666667e-06" iyz="0" izz="1.0000000000000002e-06"/>
    </inertial>
  </link>
  <joint name="support2base_link" type="fixed">
    <parent link="base_link"/>
    <child link="support"/>
    <origin xyz="0.0 0.0 0.065"/>
  </joint>
  <gazebo reference="support">
    <material>Gazebo/White</material>
  </gazebo>
  <!-- 雷达质量 -->
  <!-- 雷达关节以及link -->
  <link name="laser">
    <visual>
      <geometry>
        <cylinder length="0.05" radius="0.03"/>
      </geometry>
      <origin rpy="0.0 0.0 0.0" xyz="0.0 0.0 0.0"/>
      <material name="black"/>
    </visual>
    <collision>
      <geometry>
        <cylinder length="0.05" radius="0.03"/>
      </geometry>
      <origin rpy="0.0 0.0 0.0" xyz="0.0 0.0 0.0"/>
    </collision>
    <inertial>
      <mass value="0.1"/>
      <inertia ixx="4.333333333333333e-05" ixy="0" ixz="0" iyy="4.333333333333333e-05" iyz="0" izz="4.4999999999999996e-05"/>
    </inertial>
  </link>
  <joint name="laser2support" type="fixed">
    <parent link="support"/>
    <child link="laser"/>
    <origin xyz="0.0 0.0 0.05"/>
  </joint>
  <gazebo reference="laser">
    <material>Gazebo/Black</material>
  </gazebo>
  <!-- 雷达传感器仿真插件 -->
  <gazebo reference="laser">
    <sensor name="laser_sensor" type="ray">
      <visualize>false</visualize>
      <update_rate>10</update_rate>
      <ray>
        <scan>
          <horizontal>
            <samples>720</samples>
            <resolution>1</resolution>
            <min_angle>-3.14159</min_angle>
            <max_angle>3.14159</max_angle>
          </horizontal>
        </scan>
        <range>
          <min>0.15</min>
          <max>12.0</max>
          <resolution>0.01</resolution>
        </range>
      </ray>
      <plugin filename="libgazebo_ros_ray_sensor.so" name="gazebo_ros_laser">
        <ros>
          <remapping>~/out:=scan</remapping>
        </ros>
        <output_type>sensor_msgs/LaserScan</output_type>
        <frame_name>laser</frame_name>
      </plugin>
    </sensor>
  </gazebo>
  <!-- 绝对位姿获取插件 -->
  <gazebo>
    <plugin filename="libodom_plugin.so" name="odom_plugin">
      <topic_name>/absolute_pose</topic_name>
      <publish_rate>50</publish_rate>
    </plugin>
  </gazebo>
  <!-- 平面移动插件 -->
  <gazebo>
    <plugin filename="libgazebo_ros_planar_move.so" name="planar_move_plugin">
      <commandTopic>cmd_vel</commandTopic>
      <odometryTopic>odom</odometryTopic>
      <odometryFrame>odom</odometryFrame>
      <odometryRate>50.0</odometryRate>
      <robotBaseFrame>base_footprint</robotBaseFrame>
      <update_rate>50</update_rate>
    </plugin>
  </gazebo>
</robot>
